<?xml version="1.0"?>
<robot name="fratomo_torso_macro" xmlns:xacro="http://www.ros.org/wiki/xacro">

  <!--All units in m-kg-s-radians unit system -->
  <xacro:property name="M_PI" value="3.1415926535897931" />
  <xacro:property name="M_PI_2" value="1.570796327" />
  <xacro:property name="DEG_TO_RAD" value="0.017453293" />
  <!-- propertys for joint controllers-->
  <xacro:property name="safety_controller_k_pos" value="100" />
  <xacro:property name="safety_controller_k_vel" value="2" /> 
  <xacro:property name="joint_damping" value="0.5" />
  <xacro:property name="max_effort" value="300"/>
  <xacro:property name="max_velocity" value="10"/>

	<!--Material Definition-->  

   <material name="gray">
    <color rgba="0.5 0.5 0.5 0.5"/>
  </material>

  <material name="black">
    <color rgba="0 0 0 0.5"/>
  </material>

  <material name="purple">
    <color rgba="0.4 0.8 1 0.5"/>
  </material>

  <material name="white">
    <color rgba="1 1 1 0.5"/>
  </material>

  <material name="blue">
    <color rgba="0 0 0.8 0.5"/>
  </material>


  <!--Little helper macros to define the inertia matrix needed for links.-->
  <!--Cuboid-->
  <xacro:macro name="cuboid_inertia" params="width height length mass">
    <inertia ixx="${mass * (height * height + length * length) / 12}"
             iyy="${mass * (width * width + length * length) / 12}"
             izz="${mass * (width * width + height * height) / 12}"
             ixy="0" iyz="0" ixz="0"/>
  </xacro:macro>

  <!--Cylinder: length is along the z-axis! -->
  <xacro:macro name="cylinder_inertia" params="radius length mass">
    <inertia ixx="${mass * (3 * radius * radius + length * length) / 12}"
             izz="${mass * radius* radius / 2}"
             iyy="${mass * (3 * radius * radius + length * length) / 12}"
             ixy="0" iyz="0" ixz="0"/>
  </xacro:macro>
  <!--Trasmission macro for gazebo and controllers -->
  <xacro:macro name="transmission_block" params="joint_name">
      <transmission name="${joint_name}_tran1">
        <type>transmission_interface/SimpleTransmission</type>
        <joint name="${joint_name}">
          <hardwareInterface>hardware_interface/PositionJointInterface</hardwareInterface>
        </joint>
        <actuator name="${joint_name}_motor">
          <hardwareInterface>hardware_interface/PositionJointInterface</hardwareInterface>
          <mechanicalReduction>1</mechanicalReduction>
        </actuator>
      </transmission>
     </xacro:macro>

  <!-- WHOLE TORSO MACRO-->
  <xacro:macro name="fratomo_torso" params="parent" > 
   
   <!-- links -->
    <link name="turnable">
      <visual>
        <geometry>
          <mesh filename="package://fratomo_pro_description/meshes/turnable.stl" scale="0.001 0.001 0.001 "/>
        </geometry>
        <material name="purple"/>
        <origin rpy="0 0 0" xyz="0 0 0"/>
      </visual>
      <collision>
        <geometry>
          <mesh filename="package://fratomo_pro_description/meshes/turnable.stl" scale="0.001 0.001 0.001 "/>
        </geometry>
        <origin rpy="0 0 0" xyz="0 0 0"/>
      </collision>
      <inertial>
        <xacro:cylinder_inertia radius="0.05" length="0.11" mass="1"/>
        <mass value="1" />
        <origin xyz="0 0 0.055" />
      </inertial> 
    </link>


    <link name="torso">
      <visual>
        <geometry>
          <mesh filename="package://fratomo_pro_description/meshes/torso.stl" scale="0.001 0.001 0.001 "/>
        </geometry>
        <material name="purple"/>
        <origin rpy="0 0 0" xyz="0 0 0"/>
      </visual>
      <collision>
        <geometry>
          <mesh filename="package://fratomo_pro_description/meshes/torso.stl" scale="0.001 0.001 0.001 "/>
        </geometry>
        <origin rpy="0 0 0" xyz="0 0 0"/>
      </collision>
      <inertial>
        <xacro:cuboid_inertia width="0.05" height="0.130" length="0.2" mass="1"/>
        <mass value="1" />
        <origin xyz="0 0 0.05" />
      </inertial> 
    </link>

    <link name="neck">
      <visual>
        <geometry>
          <mesh filename="package://fratomo_pro_description/meshes/neck.stl" scale="0.001 0.001 0.001 "/>
        </geometry>
        <material name="gray"/>
        <origin rpy="0 0 0" xyz="0 0 0"/>
      </visual>
      <collision>
        <geometry>
          <mesh filename="package://fratomo_pro_description/meshes/neck.stl" scale="0.001 0.001 0.001 "/>
        </geometry>
        <origin rpy="0 0 0" xyz="0 0 0"/>
      </collision>
      <inertial>
        <xacro:cuboid_inertia width="0.05" height="0.02" length="0.09" mass="1"/>
        <mass value="0.1" />
        <origin xyz="0.02 0 0.04" />
      </inertial> 
    </link>

    <link name="head">
      <visual>
        <geometry>
          <mesh filename="package://fratomo_pro_description/meshes/head.stl" scale="0.001 0.001 0.001 "/>
        </geometry>
        <material name="blue"/>
        <origin rpy="0 -1.57075 0" xyz="0 0 0"/>
      </visual>
      <collision>
        <geometry>
          <mesh filename="package://fratomo_pro_description/meshes/head.stl" scale="0.001 0.001 0.001 "/>
        </geometry>
        <origin rpy="0 -1.57075 0" xyz="0 0 0"/>
      </collision>
      <inertial>
        <xacro:cuboid_inertia width="0.09" height="0.12" length="0.09" mass="0.2"/>
        <mass value="0.2" />
        <origin xyz="0.03 0 0.03" />
      </inertial> 
    </link>

    <link name="shoulder">
      <visual>
        <geometry>
          <mesh filename="package://fratomo_pro_description/meshes/shoulder.stl" scale="0.001 0.001 0.001 "/>
        </geometry>
        <material name="gray"/>
        <origin rpy="3.14159 0 0" xyz="0 0 0"/>
      </visual>
      <collision>
        <geometry>
          <mesh filename="package://fratomo_pro_description/meshes/shoulder.stl" scale="0.001 0.001 0.001 "/>
        </geometry>
        <origin rpy="3.14159 0 0" xyz="0 0 0"/>
      </collision>
      <inertial>
        <xacro:cuboid_inertia width="0.058" height="0.03" length="0.066" mass="0.2"/>
        <mass value="0.2" />
        <origin xyz="0.00 0.01 0.03" />
      </inertial> 

    </link>

    <link name="arm_l1">
      <visual>
        <geometry>
          <mesh filename="package://fratomo_pro_description/meshes/arm_l1.stl" scale="0.001 0.001 0.001 "/>
        </geometry>
        <material name="gray"/>
        <origin rpy="0 0 0" xyz="0 0 0"/>
      </visual>
      <collision>
        <geometry>
          <mesh filename="package://fratomo_pro_description/meshes/arm_l1.stl" scale="0.001 0.001 0.001 "/>
        </geometry>
        <origin rpy="0 0 0" xyz="0 0 0"/>
      </collision>
       <inertial>
        <xacro:cuboid_inertia width="0.045" height="0.144" length="0.02" mass="0.1"/>
        <mass value="0.1" />
        <origin xyz="0.00 -0.07 0.0" />
      </inertial> 

    </link>

    <link name="forearm">
      <visual>
        <geometry>
          <mesh filename="package://fratomo_pro_description/meshes/forearm.stl" scale="0.001 0.001 0.001 "/>
        </geometry>
        <material name="gray"/>
        <origin rpy="0 3.14159 0" xyz="0.01822 0 0"/>
      </visual>
      <collision>
        <geometry>
          <mesh filename="package://fratomo_pro_description/meshes/forearm.stl" scale="0.001 0.001 0.001 "/>
        </geometry>
        <origin rpy="0 3.14159 0" xyz="0.01822 0 0"/>
      </collision>
      <inertial>
        <!--xacro:cuboid_inertia width="0.045" height="0.170" length="0.025" mass="0.3"/-->
        <inertia ixx="0.0001" ixy="0.000"  ixz="0.000"  
                 iyy="0.0001" iyz="0.000"
                 izz="0.0001"/>
        <mass value="0.3" />
        <origin xyz="0.00 -0.04 0.0" />
      </inertial> 
    </link>

    <link name="wrist_shaft">
      <visual>
        <geometry>
          <mesh filename="package://fratomo_pro_description/meshes/wrist_shaft.stl" scale="0.001 0.001 0.001 "/>
        </geometry>
        <material name="gray"/>
        <origin rpy="0 0 1.57075" xyz="-0.115 -0.0227 0"/>
      </visual>
      <collision>
        <geometry>
          <mesh filename="package://fratomo_pro_description/meshes/wrist_shaft.stl" scale="0.001 0.001 0.001 "/>
        </geometry>
        <origin rpy="0 0 1.57075" xyz="-0.115 -0.0227 0"/>
      </collision>
       <inertial>
        <!--xacro:cuboid_inertia width="0.015" height="0.05" length="0.020" mass="0.02"/-->
        <inertia ixx="0.0001" ixy="0.000"  ixz="0.000"  
                 iyy="0.0001" iyz="0.000"
                 izz="0.0001"/>
        <mass value="0.02" />
        <origin xyz="0.008 0.0 0.0" />
      </inertial> 
    </link>


    <link name="wrist">
      <visual>
        <geometry>
          <mesh filename="package://fratomo_pro_description/meshes/wrist.stl" scale="0.001 0.001 0.001 "/>
        </geometry>
        <material name="gray"/>
        <origin rpy="0 0 1.57075" xyz="-0.1503 -0.0227 0"/>
      </visual>
      <collision>
        <geometry>
          <mesh filename="package://fratomo_pro_description/meshes/wrist.stl" scale="0.001 0.001 0.001 "/>
        </geometry>
        <origin rpy="0 0 1.57075" xyz="-0.1503 -0.0227 0"/>
      </collision>
      <inertial>
        <!--xacro:cuboid_inertia width="0.040" height="0.05" length="0.04" mass="0.1"/-->
        <inertia ixx="0.0001" ixy="0.000"  ixz="0.000"  
                 iyy="0.0001" iyz="0.000"
                 izz="0.0001"/>
        <mass value="0.1" />
        <origin xyz="0.0 0.01 0.0" />
      </inertial> 
    </link>


    <link name="gripper">
      <visual>
        <geometry>
          <mesh filename="package://fratomo_pro_description/meshes/gripperBody.stl" scale="0.001 0.001 0.001 "/>
        </geometry>
        <material name="black"/>
        <origin rpy="0 0 1.57075" xyz="0 0 0"/>
      </visual>
      <collision>
        <geometry>
          <mesh filename="package://fratomo_pro_description/meshes/gripperBody.stl" scale="0.001 0.001 0.001 "/>
        </geometry>
        <origin rpy="0 0 1.57075" xyz="0 0 0"/>
      </collision>
       <inertial>
        <!--xacro:cuboid_inertia width="0.05" height="0.06" length="0.06" mass="0.2"/-->
        <inertia ixx="0.0001" ixy="0.000"  ixz="0.000"  
                 iyy="0.0001" iyz="0.000"
                 izz="0.0001"/>
        <mass value="0.001" />
        <mass value="0.2" />
        <origin xyz="0.01 0.00 0.0" />
      </inertial> 
    </link>

    <link name="finger_l">
      <visual>
        <geometry>
          <mesh filename="package://fratomo_pro_description/meshes/finger_l.stl" scale="0.001 0.001 0.001 "/>
        </geometry>
        <material name="black"/>
        <origin rpy="0 0 1.57075" xyz="0 0 0"/>
      </visual>
      <collision>
        <geometry>
          <mesh filename="package://fratomo_pro_description/meshes/finger_l.stl" scale="0.001 0.001 0.001 "/>
        </geometry>
        <origin rpy="0 0 1.57075" xyz="0 0 0"/>
      </collision>
       <inertial>
        <inertia ixx="0.0001" ixy="0.000"  ixz="0.000"  
                 iyy="0.0001" iyz="0.000"
                 izz="0.0001"/>
        <mass value="0.001" />
        <origin xyz="0 0 0" />
      </inertial> 
    </link>

    <link name="finger_r">
      <visual>
        <geometry>
          <mesh filename="package://fratomo_pro_description/meshes/finger_r.stl" scale="0.001 0.001 0.001 "/>
        </geometry>
        <material name="black"/>
        <origin rpy="0 0 1.57075" xyz="0 0 0"/>
      </visual>
      <collision>
        <geometry>
          <mesh filename="package://fratomo_pro_description/meshes/finger_r.stl" scale="0.001 0.001 0.001 "/>
        </geometry>
        <origin rpy="0 0 1.57075" xyz="0 0 0"/>
      </collision>
      <inertial>
        <inertia ixx="0.0001" ixy="0.000"  ixz="0.000"  
                 iyy="0.0001" iyz="0.000"
                 izz="0.0001"/>
        <mass value="0.001" />
        <origin xyz="0 0 0" />
      </inertial> 
    </link>

<!-- dummy camera, ee links -->
    <link name="end_effector">
      <visual>
        <geometry>
          <sphere radius="0.003"/>
        </geometry>
      </visual>
    </link>

    <link name="camera">
      <visual>
        <geometry>
          <sphere radius="0.005"/>
        </geometry>
      </visual>
    </link>

<!-- joints -->
    <joint name="base_to_turnable" type="fixed">
        <parent link="${parent}"/>
        <child link="turnable"/>
        <origin xyz="-0.052 0 0.169"/>
    </joint>

    <joint name="turnable_to_torso" type="revolute">
        <parent link="turnable"/>
        <child link="torso"/>
        <origin xyz="0 0 0.11"/>
        <axis xyz="0 0 1"/>
        <limit effort="10.0" velocity="1" lower="-1.57075" upper="1.57075"/>
        <safety_controller soft_lower_limit="-1.57075"
                           soft_upper_limit="1.57075"
                           k_position="${safety_controller_k_pos}"
                           k_velocity="${safety_controller_k_vel}"/> 
       <dynamics damping="${joint_damping*6}"/>
    </joint>

    <joint name="torso_to_neck" type="revolute">
        <parent link="torso"/>
        <child link="neck"/>
        <origin xyz="0 0 0.2"/>
        <axis xyz="0 0 1"/>
        <limit effort="10.0" velocity="1" lower="-1.57075" upper="1.57075"/>
        <safety_controller soft_lower_limit="-1.57075"
                           soft_upper_limit="1.57075"
                           k_position="${safety_controller_k_pos}"
                           k_velocity="${safety_controller_k_vel}"/> 
       <dynamics damping="${joint_damping}"/>
    </joint>

    <joint name="neck_to_head" type="revolute">
        <parent link="neck"/>
        <child link="head"/>
        <origin rpy="0 1.57075 0" xyz="0.041 0 0.095"/>
        <axis xyz="0 1 0"/>
        <limit effort="10.0" velocity="1" lower="-1.57075" upper="0.78539"/>
        <safety_controller soft_lower_limit="-1.57075"
                           soft_upper_limit="0.78539"
                           k_position="${safety_controller_k_pos}"
                           k_velocity="${safety_controller_k_vel}"/> 
       <dynamics damping="${joint_damping}"/>
    </joint>

    <joint name="head_to_camera" type="fixed">
        <parent link="head"/>
        <child link="camera"/>
        <origin rpy="0 0 -1.57075"  xyz="0.0 0.0 0.065 "/>
    </joint>

    <joint name="torso_to_shoulder" type="revolute">
        <parent link="torso"/>
        <child link="shoulder"/>
        <origin rpy="3.14159 1.57075 0" xyz="0 -0.1325 0.150"/>
        <axis xyz="0 1 0"/>
        <limit effort="10.0" velocity="1" upper="1.57075" lower="-1.57075"/>
         <safety_controller soft_lower_limit="-1.57075"
                           soft_upper_limit="1.57075"
                           k_position="${safety_controller_k_pos}"
                           k_velocity="${safety_controller_k_vel}"/> 
       <dynamics damping="${joint_damping}"/>
    </joint>

    <joint name="shoulder_to_arm_l1" type="revolute">
        <parent link="shoulder"/>
        <child link="arm_l1"/>
        <origin rpy="3.14159 0 0" xyz="0.0 0.026 0.0"/>
        <axis xyz="1 0 0"/>
        <limit effort="10.0" velocity="1" lower="-1.57075" upper="0.78539"/>
         <safety_controller soft_lower_limit="-1.57075"
                           soft_upper_limit="0.78539"
                           k_position="${safety_controller_k_pos}"
                           k_velocity="${safety_controller_k_vel}"/> 
       <dynamics damping="${joint_damping}"/>
    </joint>

    <joint name="arm_l1_to_forearm" type="revolute">
        <parent link="arm_l1"/>
        <child link="forearm"/>
        <origin rpy="-1.57075 0 0" xyz="0.0 -0.144 0.0"/>
        <axis xyz="1 0 0"/>
        <limit effort="10.0" velocity="1" upper="1.57075" lower="-1.57075"/>
        <safety_controller soft_lower_limit="-1.57075"
                           soft_upper_limit="1.57075"
                           k_position="${safety_controller_k_pos}"
                           k_velocity="${safety_controller_k_vel}"/> 
       <dynamics damping="${joint_damping}"/>
    </joint>

    <joint name="forearm_to_wrist_shaft" type="revolute">
        <parent link="forearm"/>
        <child link="wrist_shaft"/>
        <origin rpy="0 0 -1.57075" xyz="-0.00448 -0.11507 0.0"/>
        <axis xyz="1 0 0"/>
        <limit effort="10.0" velocity="1" upper="1.57075" lower="-1.57075"/>
        <safety_controller soft_lower_limit="-1.57075"
                           soft_upper_limit="1.57075"
                           k_position="${safety_controller_k_pos}"
                           k_velocity="${safety_controller_k_vel}"/> 
       <dynamics damping="${joint_damping}"/>
    </joint>

    <joint name="wrist_shaft_to_wrist" type="revolute">
        <parent link="wrist_shaft"/>
        <child link="wrist"/>
        <origin rpy="0 0 0" xyz="0.03534 0.0 0.0"/>
        <axis xyz="0 1 0"/>
        <limit effort="10.0" velocity="1" upper="1.57075" lower="-1.57075"/>
        <safety_controller soft_lower_limit="-1.57075"
                           soft_upper_limit="1.57075"
                           k_position="${safety_controller_k_pos}"
                           k_velocity="${safety_controller_k_vel}"/> 
       <dynamics damping="${joint_damping}"/>
    </joint>

    <joint name="wrist_to_gripper" type="revolute">
        <parent link="wrist"/>
        <child link="gripper"/>
        <origin rpy="1.57075 0 0" xyz="0.0284 0.0 0.0"/>
        <axis xyz="1 0 0"/>
        <limit effort="10.0" velocity="1" upper="1.57075" lower="-1.57075"/>
        <safety_controller soft_lower_limit="-1.57075"
                           soft_upper_limit="1.57075"
                           k_position="${safety_controller_k_pos}"
                           k_velocity="${safety_controller_k_vel}"/> 
       <dynamics damping="${joint_damping}"/>
    </joint>

    <joint name="gripper_to_end_effector" type="fixed">
        <parent link="gripper"/>
        <child link="end_effector"/>
        <origin rpy="0 0 0" xyz="0.045 0.0 0.0"/>      
    </joint>

    <joint name="gripper_to_finger_l" type="prismatic">
        <parent link="gripper"/>
        <child link="finger_l"/>
        <origin rpy="0 0 0" xyz="0 0 0"/> 
        <axis xyz="0 1 0"/>
        <limit effort="10.0" velocity="1" upper="0.02" lower="0"/>  
        <safety_controller soft_lower_limit="0"
                           soft_upper_limit="0.02"
                           k_position="${safety_controller_k_pos}"
                           k_velocity="${safety_controller_k_vel}"/> 
       <dynamics damping="${joint_damping}"/>   
    </joint>

    <joint name="gripper_to_finger_r" type="prismatic">
        <parent link="gripper"/>
        <child link="finger_r"/>
        <origin rpy="0 0 0" xyz="0 0 0"/> 
        <axis xyz="0 1 0"/>
        <limit effort="10.0" velocity="1" upper="0.02" lower="0"/>     
        <mimic joint="gripper_to_finger_l" multiplier="-1" offset ="0"/>
        <safety_controller soft_lower_limit="0"
                           soft_upper_limit="0.02"
                           k_position="${safety_controller_k_pos}"
                           k_velocity="${safety_controller_k_vel}"/> 
       <dynamics damping="${joint_damping}"/>   
    </joint> 

    <xacro:transmission_block joint_name="turnable_to_torso"/>
    <xacro:transmission_block joint_name="torso_to_neck"/>
    <xacro:transmission_block joint_name="neck_to_head"/>
    <xacro:transmission_block joint_name="torso_to_shoulder"/>
    <xacro:transmission_block joint_name="shoulder_to_arm_l1"/>
    <xacro:transmission_block joint_name="arm_l1_to_forearm"/>
    <xacro:transmission_block joint_name="forearm_to_wrist_shaft"/>
    <xacro:transmission_block joint_name="wrist_shaft_to_wrist"/> 
    <xacro:transmission_block joint_name="wrist_to_gripper"/> 
    <xacro:transmission_block joint_name="gripper_to_finger_l"/>  

    <gazebo>
      <plugin name="gazebo_ros_control" filename="libgazebo_ros_control.so">
        <robotNamespace>/fratomo</robotNamespace>
        <robotParam>fratomo_robot_description</robotParam>
        <robotSimType>gazebo_ros_control/DefaultRobotHWSim</robotSimType>
        <legacyModeNS>true</legacyModeNS>
      </plugin>
    </gazebo>
    
    <gazebo reference="turnable">
      <material>Gazebo/Blue</material>
    </gazebo>
    <gazebo reference="torso">
      <material>Gazebo/Orange</material>
    </gazebo>
    <gazebo reference="neck">
      <material>Gazebo/Grey</material>
    </gazebo>
    <gazebo reference="head">
      <material>Gazebo/Blue</material>
    </gazebo>
    <gazebo reference="shoulder">
      <material>Gazebo/Grey</material>
    </gazebo>
    <gazebo reference="arm_l1">
      <material>Gazebo/Grey</material>
    </gazebo>
    <gazebo reference="forearm">
      <material>Gazebo/Grey</material>
    </gazebo>
    <gazebo reference="wrist_shaft">
      <material>Gazebo/Grey</material>
    </gazebo>
    <gazebo reference="wrist">
      <material>Gazebo/Grey</material>
    </gazebo>
    <gazebo reference="gripper">
      <material>Gazebo/Black</material>
    </gazebo>
    <gazebo reference="finger_l">
      <material>Gazebo/Black</material>
    </gazebo>
    <gazebo reference="finger_r">
      <material>Gazebo/Black</material>
    </gazebo>
 

  </xacro:macro>
</robot>

